Workbook

Sheet Sammanfattning
A1: Karlavägen 71 – budget per post och materialnivå (kr inkl. moms)
A2: Justerad budget = det största av nedlagt och kalkyl, dvs. nedlagt + återstående (kalkyl − nedlagt, aldrig under 0). Samma regel som i appens flik Ny budget.
A3: Nivåerna summerar fliken Detaljer, kolumn T–W. En tom nivå på en rad ärver beloppet från nivån ovanför (Premium ← Lyx, Medium ← Premium, Basic ← Medium). Ett belopp du skriver in i Detaljer används direkt här.
B4: Antaget ROT-avdrag i justerad budget (ändra här) | C4: -200000
A6: Post-id | B6: Post | C6: Ursprunglig offert D2053-1 | D6: Ny offert D2058 / ÄTA (dokument) | E6: Nedlagt (fakturerat) | F6: Kalkyl Lyx | G6: Kalkyl Premium | H6: Kalkyl Medium | I6: Kalkyl Basic | J6: Justerad Lyx | K6: Justerad Premium | L6: Justerad Medium | M6: Justerad Basic | N6: Justerad – ditt val | O6: Ny budget i appen 16 okt | P6: Kontroll
A7: riv | B7: Rivningsarbeten | C7: 198750 | D7: 198750 | E7: 197186 | F7: =SUMIFS(Detaljer!$T$5:$T$75,Detaljer!$A$5:$A$75,$A7) -> 198750 | G7: =SUMIFS(Detaljer!$U$5:$U$75,Detaljer!$A$5:$A$75,$A7) -> 198750 | H7: =SUMIFS(Detaljer!$V$5:$V$75,Detaljer!$A$5:$A$75,$A7) -> 198750 | I7: =SUMIFS(Detaljer!$W$5:$W$75,Detaljer!$A$5:$A$75,$A7) -> 198750 | J7: =MAX($E7,F7) -> 198750 | K7: =MAX($E7,G7) -> 198750 | L7: =MAX($E7,H7) -> 198750 | M7: =MAX($E7,I7) -> 198750 | N7: =MAX($E7,SUMIFS(Detaljer!$X$5:$X$75,Detaljer!$A$5:$A$75,$A7)) -> 198750 | O7: 198750 | P7: =IF(ABS(N7-O7)<1,"OK","Avviker") -> OK
A8: bygg | B8: Byggnadsarbeten | C8: 387500 | D8: 387500 | E8: 6561.61 | F8: =SUMIFS(Detaljer!$T$5:$T$75,Detaljer!$A$5:$A$75,$A8) -> 387500 | G8: =SUMIFS(Detaljer!$U$5:$U$75,Detaljer!$A$5:$A$75,$A8) -> 387500 | H8: =SUMIFS(Detaljer!$V$5:$V$75,Detaljer!$A$5:$A$75,$A8) -> 387500 | I8: =SUMIFS(Detaljer!$W$5:$W$75,Detaljer!$A$5:$A$75,$A8) -> 387500 | J8: =MAX($E8,F8) -> 387500 | K8: =MAX($E8,G8) -> 387500 | L8: =MAX($E8,H8) -> 387500 | M8: =MAX($E8,I8) -> 387500 | N8: =MAX($E8,SUMIFS(Detaljer!$X$5:$X$75,Detaljer!$A$5:$A$75,$A8)) -> 387500 | O8: 387500 | P8: =IF(ABS(N8-O8)<1,"OK","Avviker") -> OK
A9: mal | B9: Målningsarbeten | C9: 365000 | D9: 365000 | E9: 0 | F9: =SUMIFS(Detaljer!$T$5:$T$75,Detaljer!$A$5:$A$75,$A9) -> 365000 | G9: =SUMIFS(Detaljer!$U$5:$U$75,Detaljer!$A$5:$A$75,$A9) -> 365000 | H9: =SUMIFS(Detaljer!$V$5:$V$75,Detaljer!$A$5:$A$75,$A9) -> 365000 | I9: =SUMIFS(Detaljer!$W$5:$W$75,Detaljer!$A$5:$A$75,$A9) -> 365000 | J9: =MAX($E9,F9) -> 365000 | K9: =MAX($E9,G9) -> 365000 | L9: =MAX($E9,H9) -> 365000 | M9: =MAX($E9,I9) -> 365000 | N9: =MAX($E9,SUMIFS(Detaljer!$X$5:$X$75,Detaljer!$A$5:$A$75,$A9)) -> 365000 | O9: 365000 | P9: =IF(ABS(N9-O9)<1,"OK","Avviker") -> OK
A10: platt | B10: Plattarbeten | C10: 202500 | D10: 202500 | E10: 0 | F10: =SUMIFS(Detaljer!$T$5:$T$75,Detaljer!$A$5:$A$75,$A10) -> 202500 | G10: =SUMIFS(Detaljer!$U$5:$U$75,Detaljer!$A$5:$A$75,$A10) -> 202500 | H10: =SUMIFS(Detaljer!$V$5:$V$75,Detaljer!$A$5:$A$75,$A10) -> 202500 | I10: =SUMIFS(Detaljer!$W$5:$W$75,Detaljer!$A$5:$A$75,$A10) -> 202500 | J10: =MAX($E10,F10) -> 202500 | K10: =MAX($E10,G10) -> 202500 | L10: =MAX($E10,H10) -> 202500 | M10: =MAX($E10,I10) -> 202500 | N10: =MAX($E10,SUMIFS(Detaljer!$X$5:$X$75,Detaljer!$A$5:$A$75,$A10)) -> 202500 | O10: 202500 | P10: =IF(ABS(N10-O10)<1,"OK","Avviker") -> OK
A11: ror | B11: Rörarbeten | C11: 140000 | D11: 140000 | E11: 0 | F11: =SUMIFS(Detaljer!$T$5:$T$75,Detaljer!$A$5:$A$75,$A11) -> 140000 | G11: =SUMIFS(Detaljer!$U$5:$U$75,Detaljer!$A$5:$A$75,$A11) -> 140000 | H11: =SUMIFS(Detaljer!$V$5:$V$75,Detaljer!$A$5:$A$75,$A11) -> 140000 | I11: =SUMIFS(Detaljer!$W$5:$W$75,Detaljer!$A$5:$A$75,$A11) -> 140000 | J11: =MAX($E11,F11) -> 140000 | K11: =MAX($E11,G11) -> 140000 | L11: =MAX($E11,H11) -> 140000 | M11: =MAX($E11,I11) -> 140000 | N11: =MAX($E11,SUMIFS(Detaljer!$X$5:$X$75,Detaljer!$A$5:$A$75,$A11)) -> 140000 | O11: 140000 | P11: =IF(ABS(N11-O11)<1,"OK","Avviker") -> OK
A12: el | B12: Elarbeten | C12: 314250 | D12: 314250 | E12: 222629.68 | F12: =SUMIFS(Detaljer!$T$5:$T$75,Detaljer!$A$5:$A$75,$A12) -> 314250 | G12: =SUMIFS(Detaljer!$U$5:$U$75,Detaljer!$A$5:$A$75,$A12) -> 314250 | H12: =SUMIFS(Detaljer!$V$5:$V$75,Detaljer!$A$5:$A$75,$A12) -> 314250 | I12: =SUMIFS(Detaljer!$W$5:$W$75,Detaljer!$A$5:$A$75,$A12) -> 314250 | J12: =MAX($E12,F12) -> 314250 | K12: =MAX($E12,G12) -> 314250 | L12: =MAX($E12,H12) -> 314250 | M12: =MAX($E12,I12) -> 314250 | N12: =MAX($E12,SUMIFS(Detaljer!$X$5:$X$75,Detaljer!$A$5:$A$75,$A12)) -> 314250 | O12: 314250 | P12: =IF(ABS(N12-O12)<1,"OK","Avviker") -> OK
A13: parkett | B13: Parkettarbeten | C13: 200000 | D13: 85875 | E13: 0 | F13: =SUMIFS(Detaljer!$T$5:$T$75,Detaljer!$A$5:$A$75,$A13) -> 85875 | G13: =SUMIFS(Detaljer!$U$5:$U$75,Detaljer!$A$5:$A$75,$A13) -> 85875 | H13: =SUMIFS(Detaljer!$V$5:$V$75,Detaljer!$A$5:$A$75,$A13) -> 85875 | I13: =SUMIFS(Detaljer!$W$5:$W$75,Detaljer!$A$5:$A$75,$A13) -> 85875 | J13: =MAX($E13,F13) -> 85875 | K13: =MAX($E13,G13) -> 85875 | L13: =MAX($E13,H13) -> 85875 | M13: =MAX($E13,I13) -> 85875 | N13: =MAX($E13,SUMIFS(Detaljer!$X$5:$X$75,Detaljer!$A$5:$A$75,$A13)) -> 85875 | O13: 85875 | P13: =IF(ABS(N13-O13)<1,"OK","Avviker") -> OK
A14: puts | B14: Putsarbeten | C14: 70000 | D14: 70000 | E14: 0 | F14: =SUMIFS(Detaljer!$T$5:$T$75,Detaljer!$A$5:$A$75,$A14) -> 70000 | G14: =SUMIFS(Detaljer!$U$5:$U$75,Detaljer!$A$5:$A$75,$A14) -> 70000 | H14: =SUMIFS(Detaljer!$V$5:$V$75,Detaljer!$A$5:$A$75,$A14) -> 70000 | I14: =SUMIFS(Detaljer!$W$5:$W$75,Detaljer!$A$5:$A$75,$A14) -> 70000 | J14: =MAX($E14,F14) -> 70000 | K14: =MAX($E14,G14) -> 70000 | L14: =MAX($E14,H14) -> 70000 | M14: =MAX($E14,I14) -> 70000 | N14: =MAX($E14,SUMIFS(Detaljer!$X$5:$X$75,Detaljer!$A$5:$A$75,$A14)) -> 70000 | O14: 70000 | P14: =IF(ABS(N14-O14)<1,"OK","Avviker") -> OK
A15: vent | B15: Ventilationsarbeten | C15: 28750 | D15: 28750 | E15: 0 | F15: =SUMIFS(Detaljer!$T$5:$T$75,Detaljer!$A$5:$A$75,$A15) -> 28750 | G15: =SUMIFS(Detaljer!$U$5:$U$75,Detaljer!$A$5:$A$75,$A15) -> 28750 | H15: =SUMIFS(Detaljer!$V$5:$V$75,Detaljer!$A$5:$A$75,$A15) -> 28750 | I15: =SUMIFS(Detaljer!$W$5:$W$75,Detaljer!$A$5:$A$75,$A15) -> 28750 | J15: =MAX($E15,F15) -> 28750 | K15: =MAX($E15,G15) -> 28750 | L15: =MAX($E15,H15) -> 28750 | M15: =MAX($E15,I15) -> 28750 | N15: =MAX($E15,SUMIFS(Detaljer!$X$5:$X$75,Detaljer!$A$5:$A$75,$A15)) -> 28750 | O15: 28750 | P15: =IF(ABS(N15-O15)<1,"OK","Avviker") -> OK
A16: allm | B16: Allmänna kostnader | C16: 209250 | D16: 209250 | E16: 110864.01 | F16: =SUMIFS(Detaljer!$T$5:$T$75,Detaljer!$A$5:$A$75,$A16) -> 209250 | G16: =SUMIFS(Detaljer!$U$5:$U$75,Detaljer!$A$5:$A$75,$A16) -> 209250 | H16: =SUMIFS(Detaljer!$V$5:$V$75,Detaljer!$A$5:$A$75,$A16) -> 209250 | I16: =SUMIFS(Detaljer!$W$5:$W$75,Detaljer!$A$5:$A$75,$A16) -> 209250 | J16: =MAX($E16,F16) -> 209250 | K16: =MAX($E16,G16) -> 209250 | L16: =MAX($E16,H16) -> 209250 | M16: =MAX($E16,I16) -> 209250 | N16: =MAX($E16,SUMIFS(Detaljer!$X$5:$X$75,Detaljer!$A$5:$A$75,$A16)) -> 209250 | O16: 209250 | P16: =IF(ABS(N16-O16)<1,"OK","Avviker") -> OK
A17: sop | B17: Sophantering | C17: 76250 | D17: 76250 | E17: 28036.25 | F17: =SUMIFS(Detaljer!$T$5:$T$75,Detaljer!$A$5:$A$75,$A17) -> 76250 | G17: =SUMIFS(Detaljer!$U$5:$U$75,Detaljer!$A$5:$A$75,$A17) -> 76250 | H17: =SUMIFS(Detaljer!$V$5:$V$75,Detaljer!$A$5:$A$75,$A17) -> 76250 | I17: =SUMIFS(Detaljer!$W$5:$W$75,Detaljer!$A$5:$A$75,$A17) -> 76250 | J17: =MAX($E17,F17) -> 76250 | K17: =MAX($E17,G17) -> 76250 | L17: =MAX($E17,H17) -> 76250 | M17: =MAX($E17,I17) -> 76250 | N17: =MAX($E17,SUMIFS(Detaljer!$X$5:$X$75,Detaljer!$A$5:$A$75,$A17)) -> 76250 | O17: 76250 | P17: =IF(ABS(N17-O17)<1,"OK","Avviker") -> OK
A18: schab-bad | B18: Schablon badrum, bastu & sten | C18: 200000 | D18: 0 | E18: 0 | F18: =SUMIFS(Detaljer!$T$5:$T$75,Detaljer!$A$5:$A$75,$A18) -> 0 | G18: =SUMIFS(Detaljer!$U$5:$U$75,Detaljer!$A$5:$A$75,$A18) -> 0 | H18: =SUMIFS(Detaljer!$V$5:$V$75,Detaljer!$A$5:$A$75,$A18) -> 0 | I18: =SUMIFS(Detaljer!$W$5:$W$75,Detaljer!$A$5:$A$75,$A18) -> 0 | J18: =MAX($E18,F18) -> 0 | K18: =MAX($E18,G18) -> 0 | L18: =MAX($E18,H18) -> 0 | M18: =MAX($E18,I18) -> 0 | N18: =MAX($E18,SUMIFS(Detaljer!$X$5:$X$75,Detaljer!$A$5:$A$75,$A18)) -> 0 | O18: 0 | P18: =IF(ABS(N18-O18)<1,"OK","Avviker") -> OK
... A26: ark | B26: Arkitekt (utanför offerten) | C26: 0 | D26: 0 | E26: 142884 | F26: =SUMIFS(Detaljer!$T$5:$T$75,Detaljer!$A$5:$A$75,$A26) -> 0 | G26: =SUMIFS(Detaljer!$U$5:$U$75,Detaljer!$A$5:$A$75,$A26) -> 0 | H26: =SUMIFS(Detaljer!$V$5:$V$75,Detaljer!$A$5:$A$75,$A26) -> 0 | I26: =SUMIFS(Detaljer!$W$5:$W$75,Detaljer!$A$5:$A$75,$A26) -> 0 | J26: =MAX($E26,F26) -> 142884 | K26: =MAX($E26,G26) -> 142884 | L26: =MAX($E26,H26) -> 142884 | M26: =MAX($E26,I26) -> 142884 | N26: =MAX($E26,SUMIFS(Detaljer!$X$5:$X$75,Detaljer!$A$5:$A$75,$A26)) -> 142884 | O26: 142884 | P26: =IF(ABS(N26-O26)<1,"OK","Avviker") -> OK
B27: Totalt före ROT | C27: =SUM(C7:C26) -> 3142250 | D27: =SUM(D7:D26) -> 6603915 | E27: =SUM(E7:E26) -> 933624.21 | F27: =SUM(F7:F26) -> 6116523.8 | G27: =SUM(G7:G26) -> 5875318.8 | H27: =SUM(H7:H26) -> 5550495 | I27: =SUM(I7:I26) -> 5550495 | J27: =SUM(J7:J26) -> 6484870.4 | ... O27: =SUM(O7:O26) -> 5942120.4 | P27: =IF(ABS(N27-O27)<1,"OK","Avviker") -> OK
B28: ROT-avdrag (nedlagt = beviljat, justerat = antagande i C4) | C28: -200000 | D28: -200000 | E28: -27666 | J28: =$C$4 -> -200000 | K28: =$C$4 -> -200000 | L28: =$C$4 -> -200000 | M28: =$C$4 -> -200000 | N28: =$C$4 -> -200000
B29: Totalt efter ROT | C29: =C27+C28 -> 2942250 | D29: =D27+D28 -> 6403915 | E29: =E27+E28 -> 905958.21 | J29: =J27+J28 -> 6284870.4 | K29: =K27+K28 -> 6043665.4 | L29: =L27+L28 -> 5718841.7 | M29: =M27+M28 -> 5718841.7 | N29: =N27+N28 -> 5742120.4
B31: Skillnad mot Lyx (efter ROT) | J31: =J29-$J$29 -> 0 | K31: =K29-$J$29 -> -241205 | L31: =L29-$J$29 -> -566028.75 | M31: =M29-$J$29 -> -566028.75 | N31: =N29-$J$29 -> -542750
B32: Skillnad mot ny offert/ÄTA enligt dokumenten | J32: =J27-$D$27 -> -119044.59 | K32: =K27-$D$27 -> -360249.59 | L32: =L27-$D$27 -> -685073.34 | M32: =M27-$D$27 -> -685073.34 | N32: =N27-$D$27 -> -661794.59
A34: Läsanvisning
A35: • Blå siffror kommer från dokumenten och går att ändra. Den gula cellen är ett antagande att pröva.
A36: • Kalkyl per nivå hämtas från fliken Detaljer, kolumn T–W. Nivåerna påverkar bara ÄTA 2 och ÄTA 6, som är de enda med materialval.
A37: • Kolumnen "Justerad – ditt val" följer nivån i kolumn S i Detaljer: alt 1 (Lyx) i ÄTA 2 och klinker (Medium) i ÄTA 6, som i appen. Kontroll jämför med appen och visar Avviker när du ändrar något.
A38: • Ändra belopp i Detaljer, kolumn L, N, P eller R. En tom nivå ärver från nivån ovanför.
A39: • Nedlagt = fakturerat inkl. moms till och med faktura 132396 och 9260, fördelat per post på samma sätt som i appen.

Sheet Materialval
A1: Materialval per nivå (kr inkl. moms)
A2: Länkat från fliken Detaljer. Tom cell betyder att dokumentet inte har något alternativ på den nivån.
A4: Materialval | B4: Post | C4: Antal alternativ | D4: Lyx – produkt | E4: Lyx (kr) | F4: Premium – produkt | G4: Premium (kr) | H4: Medium – produkt | I4: Medium (kr) | J4: Basic – produkt | K4: Basic (kr) | L4: Skillnad dyraste – billigaste | M4: Ditt val
A5: Badrum: tvättställsblandare | B5: ÄTA 2 – VVS-produkter | C5: 2 | D5: =IF(Detaljer!K33="","",Detaljer!K33) -> tvättställsblandare Dornbracht Meta (Alt 1) | E5: =IF(Detaljer!L33="","",Detaljer!L33) -> 5715 | F5: =IF(Detaljer!M33="","",Detaljer!M33) -> tvättställsblandare Scandtap Equip Classic (Alt 2) | G5: =IF(Detaljer!N33="","",Detaljer!N33) -> 4556.25 | H5: =IF(Detaljer!O33="","",Detaljer!O33) | I5: =IF(Detaljer!P33="","",Detaljer!P33) | J5: =IF(Detaljer!Q33="","",Detaljer!Q33) | K5: =IF(Detaljer!R33="","",Detaljer!R33) | L5: =MAX(Detaljer!L33,Detaljer!N33,Detaljer!P33,Detaljer!R33)-MIN(Detaljer!L33,Detaljer!N33,Detaljer!P33,Detaljer!R33) -> 1158.75 | M5: =Detaljer!S33 -> Lyx
A6: Badrum: duschblandare | B6: ÄTA 2 – VVS-produkter | C6: 2 | D6: =IF(Detaljer!K34="","",Detaljer!K34) -> duschblandare Dornbracht Tara Showerpipe + handdusch (Alt 1) | E6: =IF(Detaljer!L34="","",Detaljer!L34) -> 31817.5 | F6: =IF(Detaljer!M34="","",Detaljer!M34) -> duschblandare Scandtap Steel Pleasure 2 Classic (Alt 2) | G6: =IF(Detaljer!N34="","",Detaljer!N34) -> 18811.25 | H6: =IF(Detaljer!O34="","",Detaljer!O34) | I6: =IF(Detaljer!P34="","",Detaljer!P34) | J6: =IF(Detaljer!Q34="","",Detaljer!Q34) | K6: =IF(Detaljer!R34="","",Detaljer!R34) | L6: =MAX(Detaljer!L34,Detaljer!N34,Detaljer!P34,Detaljer!R34)-MIN(Detaljer!L34,Detaljer!N34,Detaljer!P34,Detaljer!R34) -> 13006.25 | M6: =Detaljer!S34 -> Lyx
A7: Badrum: spolplatta | B7: ÄTA 2 – VVS-produkter | C7: 2 | D7: =IF(Detaljer!K35="","",Detaljer!K35) -> spolplatta Dornbracht Angular (Alt 1) | E7: =IF(Detaljer!L35="","",Detaljer!L35) -> 4750 | F7: =IF(Detaljer!M35="","",Detaljer!M35) -> spolplatta Scandtap Style Classic (Alt 2) | G7: =IF(Detaljer!N35="","",Detaljer!N35) -> 4188.75 | H7: =IF(Detaljer!O35="","",Detaljer!O35) | I7: =IF(Detaljer!P35="","",Detaljer!P35) | J7: =IF(Detaljer!Q35="","",Detaljer!Q35) | K7: =IF(Detaljer!R35="","",Detaljer!R35) | L7: =MAX(Detaljer!L35,Detaljer!N35,Detaljer!P35,Detaljer!R35)-MIN(Detaljer!L35,Detaljer!N35,Detaljer!P35,Detaljer!R35) -> 561.25 | M7: =Detaljer!S35 -> Lyx
A8: Wc: tvättställsblandare | B8: ÄTA 2 – VVS-produkter | C8: 2 | D8: =IF(Detaljer!K39="","",Detaljer!K39) -> tvättställsblandare Dornbracht Meta (Alt 1) | E8: =IF(Detaljer!L39="","",Detaljer!L39) -> 5715 | F8: =IF(Detaljer!M39="","",Detaljer!M39) -> tvättställsblandare Scandtap Equip Classic (Alt 2) | G8: =IF(Detaljer!N39="","",Detaljer!N39) -> 4556.25 | H8: =IF(Detaljer!O39="","",Detaljer!O39) | I8: =IF(Detaljer!P39="","",Detaljer!P39) | J8: =IF(Detaljer!Q39="","",Detaljer!Q39) | K8: =IF(Detaljer!R39="","",Detaljer!R39) | L8: =MAX(Detaljer!L39,Detaljer!N39,Detaljer!P39,Detaljer!R39)-MIN(Detaljer!L39,Detaljer!N39,Detaljer!P39,Detaljer!R39) -> 1158.75 | M8: =Detaljer!S39 -> Lyx
A9: Wc: spolplatta | B9: ÄTA 2 – VVS-produkter | C9: 2 | D9: =IF(Detaljer!K40="","",Detaljer!K40) -> spolplatta Dornbracht Angular (Alt 1) | E9: =IF(Detaljer!L40="","",Detaljer!L40) -> 4750 | F9: =IF(Detaljer!M40="","",Detaljer!M40) -> spolplatta Scandtap Style Classic (Alt 2) | G9: =IF(Detaljer!N40="","",Detaljer!N40) -> 4188.75 | H9: =IF(Detaljer!O40="","",Detaljer!O40) | I9: =IF(Detaljer!P40="","",Detaljer!P40) | J9: =IF(Detaljer!Q40="","",Detaljer!Q40) | K9: =IF(Detaljer!R40="","",Detaljer!R40) | L9: =MAX(Detaljer!L40,Detaljer!N40,Detaljer!P40,Detaljer!R40)-MIN(Detaljer!L40,Detaljer!N40,Detaljer!P40,Detaljer!R40) -> 561.25 | M9: =Detaljer!S40 -> Lyx
A10: Kök: blandare | B10: ÄTA 2 – VVS-produkter | C10: 3 | D10: =IF(Detaljer!K41="","",Detaljer!K41) -> blandare Dornbracht Tara Ultra Pivot (Alt 1) | E10: =IF(Detaljer!L41="","",Detaljer!L41) -> 12715 | F10: =IF(Detaljer!M41="","",Detaljer!M41) -> blandare Dornbracht Tara pull-down med dusch (Alt 2) | G10: =IF(Detaljer!N41="","",Detaljer!N41) -> 9956.25 | H10: =IF(Detaljer!O41="","",Detaljer!O41) -> blandare Scandtap Equip D Classic (Alt 3) | I10: =IF(Detaljer!P41="","",Detaljer!P41) -> 5882.5 | J10: =IF(Detaljer!Q41="","",Detaljer!Q41) | K10: =IF(Detaljer!R41="","",Detaljer!R41) | L10: =MAX(Detaljer!L41,Detaljer!N41,Detaljer!P41,Detaljer!R41)-MIN(Detaljer!L41,Detaljer!N41,Detaljer!P41,Detaljer!R41) -> 6832.5 | M10: =Detaljer!S41 -> Lyx
A11: Sten och klinker i badrum och hall | B11: ÄTA 6 – Sten & glas | C11: 3 | D11: =IF(Detaljer!K68="","",Detaljer!K68) -> Brännlyckamarmor (Alt 1) | E11: =IF(Detaljer!L68="","",Detaljer!L68) -> 600000 | F11: =IF(Detaljer!M68="","",Detaljer!M68) -> Verde Italia finslipad, inkl. stendetaljer och 1 tvättställ (Alt 2) | G11: =IF(Detaljer!N68="","",Detaljer!N68) -> 378000 | H11: =IF(Detaljer!O68="","",Detaljer!O68) -> Bricmate M Kolmården 60×60, cirka 40 m² (Alt 3) | I11: =IF(Detaljer!P68="","",Detaljer!P68) -> 57250 | J11: =IF(Detaljer!Q68="","",Detaljer!Q68) | K11: =IF(Detaljer!R68="","",Detaljer!R68) | L11: =MAX(Detaljer!L68,Detaljer!N68,Detaljer!P68,Detaljer!R68)-MIN(Detaljer!L68,Detaljer!N68,Detaljer!P68,Detaljer!R68) -> 542750 | M11: =Detaljer!S68 -> Medium
A12: Totalt | L12: =SUM(L5:L11) -> 566028.75

Sheet Detaljer
A1: Karlavägen 71 – alla budgetposter i detalj (kr inkl. moms)
A2: Källa: offert D2058 rev 1 (2026-05-08) och ÄTA 2–6 (2026-10-16), Thessén & Ek. Skriv belopp i kolumnerna Lyx, Premium, Medium eller Basic (kr) på valfri rad. En tom nivå ärver från nivån ovanför (Premium ← Lyx, Medium ← Premium, Basic ← Medium). Blå = värden från dokumenten. Svart = formler. Välj nivå per rad i kolumn S.
A3: Materialval: dyraste alternativet ligger i Lyx, därefter Premium, Medium och Basic. På övriga rader är Lyx = beloppet enligt dokumentet.
A4: Post-id | B4: Post | C4: Rad / materialval | D4: Beskrivning | E4: Typ | F4: Rum | G4: Antal | H4: Enhet | I4: À-pris (kr) | J4: Belopp enligt dokument (kr) | K4: Lyx – produkt | L4: Lyx (kr) | M4: Premium – produkt | N4: Premium (kr) | O4: Medium – produkt | P4: Medium (kr) | Q4: Basic – produkt | R4: Basic (kr) | S4: Ditt val (nivå) | T4: Scenario Lyx (kr) | U4: Scenario Premium (kr) | V4: Scenario Medium (kr) | W4: Scenario Basic (kr) | X4: Ditt val (kr)
A5: riv | B5: Rivningsarbeten
A6: riv | B6: Rivningsarbeten | C6: Spårning för ny el | E6: arbete | F6: Hela lägenheten | G6: 32 | H6: h | I6: 650 | J6: =G6*I6 -> 20800 | K6: Enligt dokument | L6: =J6 -> 20800 | S6: Lyx | T6: =L6 -> 20800 | U6: =IF(N6<>"",N6,T6) -> 20800 | V6: =IF(P6<>"",P6,U6) -> 20800 | W6: =IF(R6<>"",R6,V6) -> 20800 | X6: =IFERROR(INDEX(T6:W6,MATCH(S6,{"Lyx","Premium","Medium","Basic"},0)),T6) -> 20800
A7: riv | B7: Rivningsarbeten | C7: Rivning kök, wc, innerväggar runt wc/pentry och förråd, matta och parkett. Upptag för 2 nya dörrhål. | D7: Resten av posten, inte uppdelat i offerten | E7: blandat | F7: Hela lägenheten | J7: 177950 | K7: Enligt dokument | L7: =J7 -> 177950 | S7: Lyx | T7: =L7 -> 177950 | U7: =IF(N7<>"",N7,T7) -> 177950 | V7: =IF(P7<>"",P7,U7) -> 177950 | W7: =IF(R7<>"",R7,V7) -> 177950 | X7: =IFERROR(INDEX(T7:W7,MATCH(S7,{"Lyx","Premium","Medium","Basic"},0)),T7) -> 177950
A8: bygg | B8: Byggnadsarbeten
A9: bygg | B9: Byggnadsarbeten | C9: Byggnadsarbeten enligt offert | D9: Täckning av golv. Nya väggar runt badrum och hall, igensättning av 2 dörrhål. Nya socklar. Montering av 6 befintliga innerdörrar med omfattningar och foder. Panel och lavar i bastu. Komplettering badrum. Montering av kök och glaspartier. | E9: blandat | F9: Hela lägenheten | J9: 387500 | K9: Enligt dokument | L9: =J9 -> 387500 | S9: Lyx | T9: =L9 -> 387500 | U9: =IF(N9<>"",N9,T9) -> 387500 | V9: =IF(P9<>"",P9,U9) -> 387500 | W9: =IF(R9<>"",R9,V9) -> 387500 | X9: =IFERROR(INDEX(T9:W9,MATCH(S9,{"Lyx","Premium","Medium","Basic"},0)),T9) -> 387500
A10: mal | B10: Målningsarbeten
A11: mal | B11: Målningsarbeten | C11: Lägga i spårningar efter el | E11: arbete | F11: Hela lägenheten | G11: 32 | H11: h | I11: 650 | J11: =G11*I11 -> 20800 | K11: Enligt dokument | L11: =J11 -> 20800 | S11: Lyx | T11: =L11 -> 20800 | U11: =IF(N11<>"",N11,T11) -> 20800 | V11: =IF(P11<>"",P11,U11) -> 20800 | W11: =IF(R11<>"",R11,V11) -> 20800 | X11: =IFERROR(INDEX(T11:W11,MATCH(S11,{"Lyx","Premium","Medium","Basic"},0)),T11) -> 20800
A12: mal | B12: Målningsarbeten | C12: Spackling och målning 2–3 ggr av tak, väggar, fönster (insida) och snickerier. Jotun ingår. | D12: Resten av posten, inte uppdelat i offerten | E12: blandat | F12: Hela lägenheten | J12: 344200 | K12: Enligt dokument | L12: =J12 -> 344200 | S12: Lyx | T12: =L12 -> 344200 | U12: =IF(N12<>"",N12,T12) -> 344200 | V12: =IF(P12<>"",P12,U12) -> 344200 | W12: =IF(R12<>"",R12,V12) -> 344200 | X12: =IFERROR(INDEX(T12:W12,MATCH(S12,{"Lyx","Premium","Medium","Basic"},0)),T12) -> 344200
A13: platt | B13: Plattarbeten
A14: platt | B14: Plattarbeten | C14: Plattarbeten enligt offert | D14: Hall: tunnspackling, natursten. Badrum: flytspackling, tätskikt, sättning och fogning, kuvertskärning, inbyggnad av wc-fixtur. Bastu: flytspackling, tätskikt, sättning, sockel, kuvertskärning. | E14: blandat | F14: Våtrum + hall | J14: 202500 | K14: Enligt dokument | L14: =J14 -> 202500 | S14: Lyx | T14: =L14 -> 202500 | U14: =IF(N14<>"",N14,T14) -> 202500 | V14: =IF(P14<>"",P14,U14) -> 202500 | W14: =IF(R14<>"",R14,V14) -> 202500 | X14: =IFERROR(INDEX(T14:W14,MATCH(S14,{"Lyx","Premium","Medium","Basic"},0)),T14) -> 202500
A15: ror | B15: Rörarbeten
A16: ror | B16: Rörarbeten | C16: Rörarbeten enligt offert | D16: Demontering badrum och kök. Flytt av avlopp. 2 standardbrunnar. Tappvatten kök och badrum. Komplettering. | E16: blandat | F16: Kök + våtrum | J16: 140000 | K16: Enligt dokument | L16: =J16 -> 140000 | S16: Lyx | T16: =L16 -> 140000 | U16: =IF(N16<>"",N16,T16) -> 140000 | V16: =IF(P16<>"",P16,U16) -> 140000 | W16: =IF(R16<>"",R16,V16) -> 140000 | X16: =IFERROR(INDEX(T16:W16,MATCH(S16,{"Lyx","Premium","Medium","Basic"},0)),T16) -> 140000
A17: el | B17: Elarbeten
A18: el | B18: Elarbeten | C18: Elarbeten enligt offert | D18: Demontering. Omdragning för kök, badrum och flyttade väggar och dörrhål. Badrum: golvvärme, bastuaggregat, uttag i kommod, 4 LED-spotlights. Plejd-dimrar. Serie Renova. Inkoppling och avprovning. | E18: blandat | F18: Hela lägenheten | J18: 314250 | K18: Enligt dokument | L18: =J18 -> 314250 | S18: Lyx | T18: =L18 -> 314250 | U18: =IF(N18<>"",N18,T18) -> 314250 | V18: =IF(P18<>"",P18,U18) -> 314250 | W18: =IF(R18<>"",R18,V18) -> 314250 | X18: =IFERROR(INDEX(T18:W18,MATCH(S18,{"Lyx","Premium","Medium","Basic"},0)),T18) -> 314250
A19: parkett | B19: Parkettarbeten
A20: parkett | B20: Parkettarbeten | C20: Fiskbensparkett i vardagsrum | D20: Läggning, slipning och hårdvaxolja. Slipning och behandling av 6 trösklar. D2053-1 hade samtliga rum för 200 000 kr. | E20: blandat | F20: Vardagsrum & matsal | J20: 85875 | K20: Enligt dokument | L20: =J20 -> 85875 | S20: Lyx | T20: =L20 -> 85875 | U20: =IF(N20<>"",N20,T20) -> 85875 | V20: =IF(P20<>"",P20,U20) -> 85875 | W20: =IF(R20<>"",R20,V20) -> 85875 | X20: =IFERROR(INDEX(T20:W20,MATCH(S20,{"Lyx","Premium","Medium","Basic"},0)),T20) -> 85875
A21: puts | B21: Putsarbeten
A22: puts | B22: Putsarbeten | C22: Putslagningar efter rivning | D22: Schablon | E22: blandat | F22: Hela lägenheten | J22: 70000 | K22: Enligt dokument | L22: =J22 -> 70000 | S22: Lyx | T22: =L22 -> 70000 | U22: =IF(N22<>"",N22,T22) -> 70000 | V22: =IF(P22<>"",P22,U22) -> 70000 | W22: =IF(R22<>"",R22,V22) -> 70000 | X22: =IFERROR(INDEX(T22:W22,MATCH(S22,{"Lyx","Premium","Medium","Basic"},0)),T22) -> 70000
A23: vent | B23: Ventilationsarbeten
A24: vent | B24: Ventilationsarbeten | C24: Ventilation kök och badrum | D24: Schablon | E24: blandat | F24: Kök + våtrum | J24: 28750 | K24: Enligt dokument | L24: =J24 -> 28750 | S24: Lyx | T24: =L24 -> 28750 | U24: =IF(N24<>"",N24,T24) -> 28750 | V24: =IF(P24<>"",P24,U24) -> 28750 | W24: =IF(R24<>"",R24,V24) -> 28750 | X24: =IFERROR(INDEX(T24:W24,MATCH(S24,{"Lyx","Premium","Medium","Basic"},0)),T24) -> 28750
A25: allm | B25: Allmänna kostnader
A26: allm | B26: Allmänna kostnader | C26: Allmänna kostnader enligt offert | D26: Transporter, 1 kranlyft, arbetsledning, materialhantering, förbrukningsmaterial, etablering och avetablering. | E26: blandat | F26: Hela lägenheten | J26: 209250 | K26: Enligt dokument | L26: =J26 -> 209250 | S26: Lyx | T26: =L26 -> 209250 | U26: =IF(N26<>"",N26,T26) -> 209250 | V26: =IF(P26<>"",P26,U26) -> 209250 | W26: =IF(R26<>"",R26,V26) -> 209250 | X26: =IFERROR(INDEX(T26:W26,MATCH(S26,{"Lyx","Premium","Medium","Basic"},0)),T26) -> 209250
A27: sop | B27: Sophantering
A28: sop | B28: Sophantering | C28: Sophantering via Big Bag | D28: Sorterat | E28: övrigt | F28: Hela lägenheten | J28: 76250 | K28: Enligt dokument | L28: =J28 -> 76250 | S28: Lyx | T28: =L28 -> 76250 | U28: =IF(N28<>"",N28,T28) -> 76250 | V28: =IF(P28<>"",P28,U28) -> 76250 | W28: =IF(R28<>"",R28,V28) -> 76250 | X28: =IFERROR(INDEX(T28:W28,MATCH(S28,{"Lyx","Premium","Medium","Basic"},0)),T28) -> 76250
A29: ata2 | B29: ÄTA 2 – VVS-produkter
A30: ata2 | B30: ÄTA 2 – VVS-produkter | C30: Badrum: fixtur Geberit med inbyggd påse | E30: material | F30: Badrum & bastu | J30: 9800 | K30: Enligt dokument | L30: =J30 -> 9800 | S30: Lyx | T30: =L30 -> 9800 | U30: =IF(N30<>"",N30,T30) -> 9800 | V30: =IF(P30<>"",P30,U30) -> 9800 | W30: =IF(R30<>"",R30,V30) -> 9800 | X30: =IFERROR(INDEX(T30:W30,MATCH(S30,{"Lyx","Premium","Medium","Basic"},0)),T30) -> 9800
A31: ata2 | B31: ÄTA 2 – VVS-produkter | C31: Badrum: wc Laufen Kartell, vägghängd | E31: material | F31: Badrum & bastu | J31: 8013.75 | K31: Enligt dokument | L31: =J31 -> 8013.75 | S31: Lyx | T31: =L31 -> 8013.75 | U31: =IF(N31<>"",N31,T31) -> 8013.75 | V31: =IF(P31<>"",P31,U31) -> 8013.75 | W31: =IF(R31<>"",R31,V31) -> 8013.75 | X31: =IFERROR(INDEX(T31:W31,MATCH(S31,{"Lyx","Premium","Medium","Basic"},0)),T31) -> 8013.75
A32: ata2 | B32: ÄTA 2 – VVS-produkter | C32: Badrum: tvättställ Laufen Val med tvål-ö | E32: material | F32: Badrum & bastu | J32: 8371.25 | K32: Enligt dokument | L32: =J32 -> 8371.25 | S32: Lyx | T32: =L32 -> 8371.25 | U32: =IF(N32<>"",N32,T32) -> 8371.25 | V32: =IF(P32<>"",P32,U32) -> 8371.25 | W32: =IF(R32<>"",R32,V32) -> 8371.25 | X32: =IFERROR(INDEX(T32:W32,MATCH(S32,{"Lyx","Premium","Medium","Basic"},0)),T32) -> 8371.25
A33: ata2 | B33: ÄTA 2 – VVS-produkter | C33: Badrum: tvättställsblandare (välj ett) | D33: Alt 1: Badrum: tvättställsblandare Dornbracht Meta; Alt 2: Badrum: tvättställsblandare Scandtap Equip Classic | E33: material | F33: Badrum & bastu | K33: tvättställsblandare Dornbracht Meta (Alt 1) | L33: 5715 | M33: tvättställsblandare Scandtap Equip Classic (Alt 2) | N33: 4556.25 | S33: Lyx | T33: =L33 -> 5715 | U33: =IF(N33<>"",N33,T33) -> 4556.25 | V33: =IF(P33<>"",P33,U33) -> 4556.25 | W33: =IF(R33<>"",R33,V33) -> 4556.25 | X33: =IFERROR(INDEX(T33:W33,MATCH(S33,{"Lyx","Premium","Medium","Basic"},0)),T33) -> 5715
A34: ata2 | B34: ÄTA 2 – VVS-produkter | C34: Badrum: duschblandare (välj ett) | D34: Alt 1: Badrum: duschblandare Dornbracht Tara Showerpipe + handdusch; Alt 2: Badrum: duschblandare Scandtap Steel Pleasure 2 Classic | E34: material | F34: Badrum & bastu | K34: duschblandare Dornbracht Tara Showerpipe + handdusch (Alt 1) | L34: 31817.5 | M34: duschblandare Scandtap Steel Pleasure 2 Classic (Alt 2) | N34: 18811.25 | S34: Lyx | T34: =L34 -> 31817.5 | U34: =IF(N34<>"",N34,T34) -> 18811.25 | V34: =IF(P34<>"",P34,U34) -> 18811.25 | W34: =IF(R34<>"",R34,V34) -> 18811.25 | X34: =IFERROR(INDEX(T34:W34,MATCH(S34,{"Lyx","Premium","Medium","Basic"},0)),T34) -> 31817.5
A35: ata2 | B35: ÄTA 2 – VVS-produkter | C35: Badrum: spolplatta (välj ett) | D35: Alt 1: Badrum: spolplatta Dornbracht Angular; Alt 2: Badrum: spolplatta Scandtap Style Classic | E35: material | F35: Badrum & bastu | K35: spolplatta Dornbracht Angular (Alt 1) | L35: 4750 | M35: spolplatta Scandtap Style Classic (Alt 2) | N35: 4188.75 | S35: Lyx | T35: =L35 -> 4750 | U35: =IF(N35<>"",N35,T35) -> 4188.75 | V35: =IF(P35<>"",P35,U35) -> 4188.75 | W35: =IF(R35<>"",R35,V35) -> 4188.75 | X35: =IFERROR(INDEX(T35:W35,MATCH(S35,{"Lyx","Premium","Medium","Basic"},0)),T35) -> 4750
A36: ata2 | B36: ÄTA 2 – VVS-produkter | C36: Badrum: extra arbete Uni-drain | E36: arbete | F36: Badrum & bastu | J36: 12250 | K36: Enligt dokument | L36: =J36 -> 12250 | S36: Lyx | T36: =L36 -> 12250 | U36: =IF(N36<>"",N36,T36) -> 12250 | V36: =IF(P36<>"",P36,U36) -> 12250 | W36: =IF(R36<>"",R36,V36) -> 12250 | X36: =IFERROR(INDEX(T36:W36,MATCH(S36,{"Lyx","Premium","Medium","Basic"},0)),T36) -> 12250
A37: ata2 | B37: ÄTA 2 – VVS-produkter | C37: Wc: fixtur Geberit med inbyggd påse | E37: material | F37: WC | J37: 9800 | K37: Enligt dokument | L37: =J37 -> 9800 | S37: Lyx | T37: =L37 -> 9800 | U37: =IF(N37<>"",N37,T37) -> 9800 | V37: =IF(P37<>"",P37,U37) -> 9800 | W37: =IF(R37<>"",R37,V37) -> 9800 | X37: =IFERROR(INDEX(T37:W37,MATCH(S37,{"Lyx","Premium","Medium","Basic"},0)),T37) -> 9800
A38: ata2 | B38: ÄTA 2 – VVS-produkter | C38: Wc: wc Laufen Kartell, vägghängd | E38: material | F38: WC | J38: 8013.75 | K38: Enligt dokument | L38: =J38 -> 8013.75 | S38: Lyx | T38: =L38 -> 8013.75 | U38: =IF(N38<>"",N38,T38) -> 8013.75 | V38: =IF(P38<>"",P38,U38) -> 8013.75 | W38: =IF(R38<>"",R38,V38) -> 8013.75 | X38: =IFERROR(INDEX(T38:W38,MATCH(S38,{"Lyx","Premium","Medium","Basic"},0)),T38) -> 8013.75
A39: ata2 | B39: ÄTA 2 – VVS-produkter | C39: Wc: tvättställsblandare (välj ett) | D39: Alt 1: Wc: tvättställsblandare Dornbracht Meta; Alt 2: Wc: tvättställsblandare Scandtap Equip Classic | E39: material | F39: WC | K39: tvättställsblandare Dornbracht Meta (Alt 1) | L39: 5715 | M39: tvättställsblandare Scandtap Equip Classic (Alt 2) | N39: 4556.25 | S39: Lyx | T39: =L39 -> 5715 | U39: =IF(N39<>"",N39,T39) -> 4556.25 | V39: =IF(P39<>"",P39,U39) -> 4556.25 | W39: =IF(R39<>"",R39,V39) -> 4556.25 | X39: =IFERROR(INDEX(T39:W39,MATCH(S39,{"Lyx","Premium","Medium","Basic"},0)),T39) -> 5715
A40: ata2 | B40: ÄTA 2 – VVS-produkter | C40: Wc: spolplatta (välj ett) | D40: Alt 1: Wc: spolplatta Dornbracht Angular; Alt 2: Wc: spolplatta Scandtap Style Classic | E40: material | F40: WC | K40: spolplatta Dornbracht Angular (Alt 1) | L40: 4750 | M40: spolplatta Scandtap Style Classic (Alt 2) | N40: 4188.75 | S40: Lyx | T40: =L40 -> 4750 | U40: =IF(N40<>"",N40,T40) -> 4188.75 | V40: =IF(P40<>"",P40,U40) -> 4188.75 | W40: =IF(R40<>"",R40,V40) -> 4188.75 | X40: =IFERROR(INDEX(T40:W40,MATCH(S40,{"Lyx","Premium","Medium","Basic"},0)),T40) -> 4750
...

Sheet Fakturor
A1: Fakturerat hittills (kr)
A2: Källa: inlästa fakturor från Thessén & Ek och arkitekten. 132354 med beslutat ROT-avdrag 27 666 kr.
A4: Datum | B4: Leverantör | C4: Fakturanr | D4: Typ | E4: Exkl. moms | F4: Moms | G4: Öresavrundning | H4: Inkl. moms | I4: ROT-avdrag | J4: Att betala | K4: Förfaller
A5: 2026-08-15 | B5: Arkitekt V. Erlandsson | C5: 9248 | D5: Grund | E5: 19958.4 | F5: 4989.6 | G5: 0 | H5: =E5+F5+G5 -> 24948 | I5: 0 | J5: =H5+I5 -> 24948 | K5: 2026-08-30
A6: 2026-08-31 | B6: Thessén & Ek | C6: 132354 | D6: Grund | E6: 167883.2 | F6: 41970.8 | G6: 0 | H6: =E6+F6+G6 -> 209854 | I6: -27666 | J6: =H6+I6 -> 182188 | K6: 2026-09-10
A7: 2026-08-31 | B7: Thessén & Ek | C7: 132355 | D7: ÄTA | E7: 4312.56 | F7: 1078.14 | G7: 0.3 | H7: =E7+F7+G7 -> 5391 | I7: 0 | J7: =H7+I7 -> 5391 | K7: 2026-09-10
A8: 2026-08-31 | B8: Thessén & Ek | C8: 132370 | D8: ÄTA | E8: 55988.8 | F8: 13997.2 | G8: 0 | H8: =E8+F8+G8 -> 69986 | I8: 0 | J8: =H8+I8 -> 69986 | K8: 2026-09-30
A9: 2026-09-07 | B9: Arkitekt V. Erlandsson | C9: 9256 | D9: Grund | E9: 17236.8 | F9: 4309.2 | G9: 0 | H9: =E9+F9+G9 -> 21546 | I9: 0 | J9: =H9+I9 -> 21546 | K9: 2026-09-22
A10: 2026-09-07 | B10: Arkitekt V. Erlandsson | C10: 9257 | D10: Grund | E10: 22680 | F10: 5670 | G10: 0 | H10: =E10+F10+G10 -> 28350 | I10: 0 | J10: =H10+I10 -> 28350 | K10: 2026-09-22
A11: 2026-09-25 | B11: Thessén & Ek | C11: 132387 | D11: Grund | E11: 44058.91 | F11: 11014.73 | G11: 0.36 | H11: =E11+F11+G11 -> 55074 | I11: 0 | J11: =H11+I11 -> 55074 | K11: 2026-10-05
A12: 2026-09-25 | B12: Thessén & Ek | C12: 132388 | D12: ÄTA | E12: 67332.33 | F12: 16833.08 | G12: -0.41 | H12: =E12+F12+G12 -> 84165 | I12: 0 | J12: =H12+I12 -> 84165 | K12: 2026-10-05
A13: 2026-10-07 | B13: Arkitekt V. Erlandsson | C13: 9260 | D13: Grund | E13: 54432 | F13: 13608 | G13: 0 | H13: =E13+F13+G13 -> 68040 | I13: 0 | J13: =H13+I13 -> 68040 | K13: 2026-10-22
A14: 2026-10-15 | B14: Thessén & Ek | C14: 132395 | D14: Grund | E14: 240279.93 | F14: 60069.98 | G14: 0.09 | H14: =E14+F14+G14 -> 300350 | I14: 0 | J14: =H14+I14 -> 300350 | K14: 2026-10-25
A15: 2026-10-15 | B15: Thessén & Ek | C15: 132396 | D15: ÄTA | E15: 52736.44 | F15: 13184.11 | G15: 0.45 | H15: =E15+F15+G15 -> 65921 | I15: 0 | J15: =H15+I15 -> 65921 | K15: 2026-10-25
B16: Totalt | E16: =SUM(E5:E15) -> 746899.37 | F16: =SUM(F5:F15) -> 186724.84 | G16: =SUM(G5:G15) -> 0.79 | H16: =SUM(H5:H15) -> 933625 | I16: =SUM(I5:I15) -> -27666 | J16: =SUM(J5:J15) -> 905959

Sheet Antaganden
A1: Antaganden och källor
A3: Belopp | B3: Kronor inkl. 25 % moms, som i offerten och ÄTA:orna.
A4: Nivåer | B4: Inom varje materialval sorteras alternativen efter pris: dyraste = Lyx, näst dyraste = Premium, sedan Medium och Basic.
A5: Saknad nivå | B5: En tom nivå på en rad ärver beloppet från nivån ovanför: Premium ← Lyx, Medium ← Premium, Basic ← Medium. Är alla tomma blir det Lyx. Inget materialval har fyra alternativ, så Basic ärver Medium eller Premium.
A6: Egna belopp | B6: Skriv ett belopp i Lyx, Premium, Medium eller Basic (kr) på valfri rad i Detaljer. Det används direkt i scenarierna och i Sammanfattning. 0 räknas som ett belopp. Töm cellen för att ärva igen.
A7: Brännlyckamarmor | B7: Lyx i ÄTA 6 är stenfirmans bedömning, 550 000–600 000 kr, inte ett offertpris. 600 000 kr används.
A8: Klinker | B8: Klinker (Medium i ÄTA 6) kräver ytterligare tvättställ och bänkskivor i båda badrummen. De är inte prissatta och ingår inte.
A9: Montering 812,50 kr/h | B9: ÄTA 4 och 6 debiterar 812,50 kr/h mot avtalade 650 kr/h inkl. moms. Ändra À-pris i Detaljer för att räkna med avtalat pris.
A10: Ej prissatt | B10: Armaturer (ÄTA 3), gardinskenor, samt material, transport och konstruktion för glasblock (ÄTA 6) ligger på 0 kr.
A11: Typ | B11: Arbete, material, blandat (arbete och material i samma belopp) eller övrigt. Bedömt utifrån dokumentens text.
A12: Rum | B12: Bara där dokumentet anger rum. Rader för flera rum har kombinerade rumsnamn.
A13: Ditt val | B13: Valen sparade i appen 16 okt: alt 1 i ÄTA 2 och klinker i ÄTA 6. Ett eget alternativ på 0 kr i ÄTA 2 (spolplatta badrum) är inte valt och ingår inte.
